Workbook

Sheet EMI Calculator
B2: Loan Amount | C2: 500000
B3: Annual Interest % | C3: 9
B4: Years | C4: 5
B5: Months | C5: =C4*12 -> 60
B7: Monthly EMI | C7: =-PMT(C3/12/100,C5,C2) -> 10379.178

Sheet EMI Schedule
A1: Month | B1: Opening | C1: EMI | D1: Interest | E1: Principal | F1: Closing
A2: 1 | B2: ='EMI Calculator'!C2 -> 500000 | C2: ='EMI Calculator'!C7 -> 10379.178 | D2: =-IPMT('EMI Calculator'!C3/12/100,A2,'EMI Calculator'!C5,'EMI Calculator'!C2) -> 3750 | E2: =-PPMT('EMI Calculator'!C3/12/100,A2,'EMI Calculator'!C5,'EMI Calculator'!C2) -> 6629.1776 | F2: =B2-E2 -> 493370.82
A3: 2 | B3: =F2 -> 493370.82 | C3: ='EMI Calculator'!C7 -> 10379.178 | D3: =-IPMT('EMI Calculator'!C3/12/100,A3,'EMI Calculator'!C5,'EMI Calculator'!C2) -> 3700.2812 | E3: =-PPMT('EMI Calculator'!C3/12/100,A3,'EMI Calculator'!C5,'EMI Calculator'!C2) -> 6678.8964 | F3: =B3-E3 -> 486691.93
A4: 3 | B4: =F3 -> 486691.93 | C4: ='EMI Calculator'!C7 -> 10379.178 | D4: =-IPMT('EMI Calculator'!C3/12/100,A4,'EMI Calculator'!C5,'EMI Calculator'!C2) -> 3650.1894 | E4: =-PPMT('EMI Calculator'!C3/12/100,A4,'EMI Calculator'!C5,'EMI Calculator'!C2) -> 6728.9882 | F4: =B4-E4 -> 479962.94
A5: 4 | B5: =F4 -> 479962.94 | C5: ='EMI Calculator'!C7 -> 10379.178 | D5: =-IPMT('EMI Calculator'!C3/12/100,A5,'EMI Calculator'!C5,'EMI Calculator'!C2) -> 3599.722 | E5: =-PPMT('EMI Calculator'!C3/12/100,A5,'EMI Calculator'!C5,'EMI Calculator'!C2) -> 6779.4556 | F5: =B5-E5 -> 473183.48
A6: 5 | B6: =F5 -> 473183.48 | C6: ='EMI Calculator'!C7 -> 10379.178 | D6: =-IPMT('EMI Calculator'!C3/12/100,A6,'EMI Calculator'!C5,'EMI Calculator'!C2) -> 3548.8761 | E6: =-PPMT('EMI Calculator'!C3/12/100,A6,'EMI Calculator'!C5,'EMI Calculator'!C2) -> 6830.3015 | F6: =B6-E6 -> 466353.18
A7: 6 | B7: =F6 -> 466353.18 | C7: ='EMI Calculator'!C7 -> 10379.178 | D7: =-IPMT('EMI Calculator'!C3/12/100,A7,'EMI Calculator'!C5,'EMI Calculator'!C2) -> 3497.6489 | E7: =-PPMT('EMI Calculator'!C3/12/100,A7,'EMI Calculator'!C5,'EMI Calculator'!C2) -> 6881.5288 | F7: =B7-E7 -> 459471.65
A8: 7 | B8: =F7 -> 459471.65 | C8: ='EMI Calculator'!C7 -> 10379.178 | D8: =-IPMT('EMI Calculator'!C3/12/100,A8,'EMI Calculator'!C5,'EMI Calculator'!C2) -> 3446.0374 | E8: =-PPMT('EMI Calculator'!C3/12/100,A8,'EMI Calculator'!C5,'EMI Calculator'!C2) -> 6933.1402 | F8: =B8-E8 -> 452538.51
A9: 8 | B9: =F8 -> 452538.51 | C9: ='EMI Calculator'!C7 -> 10379.178 | D9: =-IPMT('EMI Calculator'!C3/12/100,A9,'EMI Calculator'!C5,'EMI Calculator'!C2) -> 3394.0388 | E9: =-PPMT('EMI Calculator'!C3/12/100,A9,'EMI Calculator'!C5,'EMI Calculator'!C2) -> 6985.1388 | F9: =B9-E9 -> 445553.37
A10: 9 | B10: =F9 -> 445553.37 | C10: ='EMI Calculator'!C7 -> 10379.178 | D10: =-IPMT('EMI Calculator'!C3/12/100,A10,'EMI Calculator'!C5,'EMI Calculator'!C2) -> 3341.6503 | E10: =-PPMT('EMI Calculator'!C3/12/100,A10,'EMI Calculator'!C5,'EMI Calculator'!C2) -> 7037.5273 | F10: =B10-E10 -> 438515.85
A11: 10 | B11: =F10 -> 438515.85 | C11: ='EMI Calculator'!C7 -> 10379.178 | D11: =-IPMT('EMI Calculator'!C3/12/100,A11,'EMI Calculator'!C5,'EMI Calculator'!C2) -> 3288.8688 | E11: =-PPMT('EMI Calculator'!C3/12/100,A11,'EMI Calculator'!C5,'EMI Calculator'!C2) -> 7090.3088 | F11: =B11-E11 -> 431425.54
A12: 11 | B12: =F11 -> 431425.54 | C12: ='EMI Calculator'!C7 -> 10379.178 | D12: =-IPMT('EMI Calculator'!C3/12/100,A12,'EMI Calculator'!C5,'EMI Calculator'!C2) -> 3235.6915 | E12: =-PPMT('EMI Calculator'!C3/12/100,A12,'EMI Calculator'!C5,'EMI Calculator'!C2) -> 7143.4861 | F12: =B12-E12 -> 424282.05
A13: 12 | B13: =F12 -> 424282.05 | C13: ='EMI Calculator'!C7 -> 10379.178 | D13: =-IPMT('EMI Calculator'!C3/12/100,A13,'EMI Calculator'!C5,'EMI Calculator'!C2) -> 3182.1154 | E13: =-PPMT('EMI Calculator'!C3/12/100,A13,'EMI Calculator'!C5,'EMI Calculator'!C2) -> 7197.0622 | F13: =B13-E13 -> 417084.99
A14: 13 | B14: =F13 -> 417084.99 | C14: ='EMI Calculator'!C7 -> 10379.178 | D14: =-IPMT('EMI Calculator'!C3/12/100,A14,'EMI Calculator'!C5,'EMI Calculator'!C2) -> 3128.1374 | E14: =-PPMT('EMI Calculator'!C3/12/100,A14,'EMI Calculator'!C5,'EMI Calculator'!C2) -> 7251.0402 | F14: =B14-E14 -> 409833.95
A15: 14 | B15: =F14 -> 409833.95 | C15: ='EMI Calculator'!C7 -> 10379.178 | D15: =-IPMT('EMI Calculator'!C3/12/100,A15,'EMI Calculator'!C5,'EMI Calculator'!C2) -> 3073.7546 | E15: =-PPMT('EMI Calculator'!C3/12/100,A15,'EMI Calculator'!C5,'EMI Calculator'!C2) -> 7305.423 | F15: =B15-E15 -> 402528.53
A16: 15 | B16: =F15 -> 402528.53 | C16: ='EMI Calculator'!C7 -> 10379.178 | D16: =-IPMT('EMI Calculator'!C3/12/100,A16,'EMI Calculator'!C5,'EMI Calculator'!C2) -> 3018.9639 | E16: =-PPMT('EMI Calculator'!C3/12/100,A16,'EMI Calculator'!C5,'EMI Calculator'!C2) -> 7360.2137 | F16: =B16-E16 -> 395168.31
A17: 16 | B17: =F16 -> 395168.31 | C17: ='EMI Calculator'!C7 -> 10379.178 | D17: =-IPMT('EMI Calculator'!C3/12/100,A17,'EMI Calculator'!C5,'EMI Calculator'!C2) -> 2963.7623 | E17: =-PPMT('EMI Calculator'!C3/12/100,A17,'EMI Calculator'!C5,'EMI Calculator'!C2) -> 7415.4153 | F17: =B17-E17 -> 387752.9
A18: 17 | B18: =F17 -> 387752.9 | C18: ='EMI Calculator'!C7 -> 10379.178 | D18: =-IPMT('EMI Calculator'!C3/12/100,A18,'EMI Calculator'!C5,'EMI Calculator'!C2) -> 2908.1467 | E18: =-PPMT('EMI Calculator'!C3/12/100,A18,'EMI Calculator'!C5,'EMI Calculator'!C2) -> 7471.0309 | F18: =B18-E18 -> 380281.87
A19: 18 | B19: =F18 -> 380281.87 | C19: ='EMI Calculator'!C7 -> 10379.178 | D19: =-IPMT('EMI Calculator'!C3/12/100,A19,'EMI Calculator'!C5,'EMI Calculator'!C2) -> 2852.114 | E19: =-PPMT('EMI Calculator'!C3/12/100,A19,'EMI Calculator'!C5,'EMI Calculator'!C2) -> 7527.0636 | F19: =B19-E19 -> 372754.8
A20: 19 | B20: =F19 -> 372754.8 | C20: ='EMI Calculator'!C7 -> 10379.178 | D20: =-IPMT('EMI Calculator'!C3/12/100,A20,'EMI Calculator'!C5,'EMI Calculator'!C2) -> 2795.661 | E20: =-PPMT('EMI Calculator'!C3/12/100,A20,'EMI Calculator'!C5,'EMI Calculator'!C2) -> 7583.5166 | F20: =B20-E20 -> 365171.29
A21: 20 | B21: =F20 -> 365171.29 | C21: ='EMI Calculator'!C7 -> 10379.178 | D21: =-IPMT('EMI Calculator'!C3/12/100,A21,'EMI Calculator'!C5,'EMI Calculator'!C2) -> 2738.7846 | E21: =-PPMT('EMI Calculator'!C3/12/100,A21,'EMI Calculator'!C5,'EMI Calculator'!C2) -> 7640.393 | F21: =B21-E21 -> 357530.89
A22: 21 | B22: =F21 -> 357530.89 | C22: ='EMI Calculator'!C7 -> 10379.178 | D22: =-IPMT('EMI Calculator'!C3/12/100,A22,'EMI Calculator'!C5,'EMI Calculator'!C2) -> 2681.4817 | E22: =-PPMT('EMI Calculator'!C3/12/100,A22,'EMI Calculator'!C5,'EMI Calculator'!C2) -> 7697.6959 | F22: =B22-E22 -> 349833.2
A23: 22 | B23: =F22 -> 349833.2 | C23: ='EMI Calculator'!C7 -> 10379.178 | D23: =-IPMT('EMI Calculator'!C3/12/100,A23,'EMI Calculator'!C5,'EMI Calculator'!C2) -> 2623.749 | E23: =-PPMT('EMI Calculator'!C3/12/100,A23,'EMI Calculator'!C5,'EMI Calculator'!C2) -> 7755.4286 | F23: =B23-E23 -> 342077.77
A24: 23 | B24: =F23 -> 342077.77 | C24: ='EMI Calculator'!C7 -> 10379.178 | D24: =-IPMT('EMI Calculator'!C3/12/100,A24,'EMI Calculator'!C5,'EMI Calculator'!C2) -> 2565.5833 | E24: =-PPMT('EMI Calculator'!C3/12/100,A24,'EMI Calculator'!C5,'EMI Calculator'!C2) -> 7813.5944 | F24: =B24-E24 -> 334264.17
A25: 24 | B25: =F24 -> 334264.17 | C25: ='EMI Calculator'!C7 -> 10379.178 | D25: =-IPMT('EMI Calculator'!C3/12/100,A25,'EMI Calculator'!C5,'EMI Calculator'!C2) -> 2506.9813 | E25: =-PPMT('EMI Calculator'!C3/12/100,A25,'EMI Calculator'!C5,'EMI Calculator'!C2) -> 7872.1963 | F25: =B25-E25 -> 326391.98
A26: 25 | B26: =F25 -> 326391.98 | C26: ='EMI Calculator'!C7 -> 10379.178 | D26: =-IPMT('EMI Calculator'!C3/12/100,A26,'EMI Calculator'!C5,'EMI Calculator'!C2) -> 2447.9398 | E26: =-PPMT('EMI Calculator'!C3/12/100,A26,'EMI Calculator'!C5,'EMI Calculator'!C2) -> 7931.2378 | F26: =B26-E26 -> 318460.74
A27: 26 | B27: =F26 -> 318460.74 | C27: ='EMI Calculator'!C7 -> 10379.178 | D27: =-IPMT('EMI Calculator'!C3/12/100,A27,'EMI Calculator'!C5,'EMI Calculator'!C2) -> 2388.4555 | E27: =-PPMT('EMI Calculator'!C3/12/100,A27,'EMI Calculator'!C5,'EMI Calculator'!C2) -> 7990.7221 | F27: =B27-E27 -> 310470.02
A28: 27 | B28: =F27 -> 310470.02 | C28: ='EMI Calculator'!C7 -> 10379.178 | D28: =-IPMT('EMI Calculator'!C3/12/100,A28,'EMI Calculator'!C5,'EMI Calculator'!C2) -> 2328.5251 | E28: =-PPMT('EMI Calculator'!C3/12/100,A28,'EMI Calculator'!C5,'EMI Calculator'!C2) -> 8050.6525 | F28: =B28-E28 -> 302419.36
A29: 28 | B29: =F28 -> 302419.36 | C29: ='EMI Calculator'!C7 -> 10379.178 | D29: =-IPMT('EMI Calculator'!C3/12/100,A29,'EMI Calculator'!C5,'EMI Calculator'!C2) -> 2268.1452 | E29: =-PPMT('EMI Calculator'!C3/12/100,A29,'EMI Calculator'!C5,'EMI Calculator'!C2) -> 8111.0324 | F29: =B29-E29 -> 294308.33
A30: 29 | B30: =F29 -> 294308.33 | C30: ='EMI Calculator'!C7 -> 10379.178 | D30: =-IPMT('EMI Calculator'!C3/12/100,A30,'EMI Calculator'!C5,'EMI Calculator'!C2) -> 2207.3125 | E30: =-PPMT('EMI Calculator'!C3/12/100,A30,'EMI Calculator'!C5,'EMI Calculator'!C2) -> 8171.8651 | F30: =B30-E30 -> 286136.47
A31: 30 | B31: =F30 -> 286136.47 | C31: ='EMI Calculator'!C7 -> 10379.178 | D31: =-IPMT('EMI Calculator'!C3/12/100,A31,'EMI Calculator'!C5,'EMI Calculator'!C2) -> 2146.0235 | E31: =-PPMT('EMI Calculator'!C3/12/100,A31,'EMI Calculator'!C5,'EMI Calculator'!C2) -> 8233.1541 | F31: =B31-E31 -> 277903.31
A32: 31 | B32: =F31 -> 277903.31 | C32: ='EMI Calculator'!C7 -> 10379.178 | D32: =-IPMT('EMI Calculator'!C3/12/100,A32,'EMI Calculator'!C5,'EMI Calculator'!C2) -> 2084.2748 | E32: =-PPMT('EMI Calculator'!C3/12/100,A32,'EMI Calculator'!C5,'EMI Calculator'!C2) -> 8294.9028 | F32: =B32-E32 -> 269608.41
A33: 32 | B33: =F32 -> 269608.41 | C33: ='EMI Calculator'!C7 -> 10379.178 | D33: =-IPMT('EMI Calculator'!C3/12/100,A33,'EMI Calculator'!C5,'EMI Calculator'!C2) -> 2022.0631 | E33: =-PPMT('EMI Calculator'!C3/12/100,A33,'EMI Calculator'!C5,'EMI Calculator'!C2) -> 8357.1145 | F33: =B33-E33 -> 261251.3
A34: 33 | B34: =F33 -> 261251.3 | C34: ='EMI Calculator'!C7 -> 10379.178 | D34: =-IPMT('EMI Calculator'!C3/12/100,A34,'EMI Calculator'!C5,'EMI Calculator'!C2) -> 1959.3847 | E34: =-PPMT('EMI Calculator'!C3/12/100,A34,'EMI Calculator'!C5,'EMI Calculator'!C2) -> 8419.7929 | F34: =B34-E34 -> 252831.5
A35: 34 | B35: =F34 -> 252831.5 | C35: ='EMI Calculator'!C7 -> 10379.178 | D35: =-IPMT('EMI Calculator'!C3/12/100,A35,'EMI Calculator'!C5,'EMI Calculator'!C2) -> 1896.2363 | E35: =-PPMT('EMI Calculator'!C3/12/100,A35,'EMI Calculator'!C5,'EMI Calculator'!C2) -> 8482.9413 | F35: =B35-E35 -> 244348.56
A36: 35 | B36: =F35 -> 244348.56 | C36: ='EMI Calculator'!C7 -> 10379.178 | D36: =-IPMT('EMI Calculator'!C3/12/100,A36,'EMI Calculator'!C5,'EMI Calculator'!C2) -> 1832.6142 | E36: =-PPMT('EMI Calculator'!C3/12/100,A36,'EMI Calculator'!C5,'EMI Calculator'!C2) -> 8546.5634 | F36: =B36-E36 -> 235802
A37: 36 | B37: =F36 -> 235802 | C37: ='EMI Calculator'!C7 -> 10379.178 | D37: =-IPMT('EMI Calculator'!C3/12/100,A37,'EMI Calculator'!C5,'EMI Calculator'!C2) -> 1768.515 | E37: =-PPMT('EMI Calculator'!C3/12/100,A37,'EMI Calculator'!C5,'EMI Calculator'!C2) -> 8610.6626 | F37: =B37-E37 -> 227191.34
A38: 37 | B38: =F37 -> 227191.34 | C38: ='EMI Calculator'!C7 -> 10379.178 | D38: =-IPMT('EMI Calculator'!C3/12/100,A38,'EMI Calculator'!C5,'EMI Calculator'!C2) -> 1703.935 | E38: =-PPMT('EMI Calculator'!C3/12/100,A38,'EMI Calculator'!C5,'EMI Calculator'!C2) -> 8675.2426 | F38: =B38-E38 -> 218516.09
A39: 38 | B39: =F38 -> 218516.09 | C39: ='EMI Calculator'!C7 -> 10379.178 | D39: =-IPMT('EMI Calculator'!C3/12/100,A39,'EMI Calculator'!C5,'EMI Calculator'!C2) -> 1638.8707 | E39: =-PPMT('EMI Calculator'!C3/12/100,A39,'EMI Calculator'!C5,'EMI Calculator'!C2) -> 8740.3069 | F39: =B39-E39 -> 209775.79
A40: 39 | B40: =F39 -> 209775.79 | C40: ='EMI Calculator'!C7 -> 10379.178 | D40: =-IPMT('EMI Calculator'!C3/12/100,A40,'EMI Calculator'!C5,'EMI Calculator'!C2) -> 1573.3184 | E40: =-PPMT('EMI Calculator'!C3/12/100,A40,'EMI Calculator'!C5,'EMI Calculator'!C2) -> 8805.8592 | F40: =B40-E40 -> 200969.93
...

Sheet Practice
A1: Loan | B1: Rate | C1: Years | D1: EMI | E1: totalpay | F1: Iterest
A2: 200000 | B2: 8.5 | C2: 3 | D2: =PMT(B2/12/100,C2*12,-A2) -> 6313.5075 | E2: =D2*36 -> 227286.27 | F2: =E2-A2 -> 27286.269
A3: 500000 | B3: 9 | C3: 5 | D3: =PMT(B3/12/100,C3*12,-A3) -> 10379.178 | E3: =D3*36 -> 373650.39 | F3: =E3-A3 -> -126349.61
A4: 850000 | B4: 10.5 | C4: 7 | D4: =PMT(B4/12/100,C4*12,-A4) -> 14331.572 | E4: =D4*36 -> 515936.6 | F4: =E4-A4 -> -334063.4
